Workbook
Name Slicer_Category: #N/A
Name Slicer_Customer_Segment: #N/A
Name Slicer_Order_Status: #N/A
Name Slicer_Payment_Mode: #N/A
Name Slicer_Region: #N/A
Name Slicer_Shipping_Mode: #N/A

Sheet Data
A1: Order_ID | B1: Order_Date | C1: Customer_ID | D1: Customer_Name | E1: Gender | F1: Age | G1: City | H1: State | I1: Region | J1: Product_ID | K1: Product_Name | L1: Category | M1: Sub_Category | N1: Brand | O1: Quantity | P1: Unit_Price | Q1: Discount | R1: Sales | S1: Cost | T1: Profit | U1: Payment_Mode | V1: Order_Status | W1: Customer_Segment | X1: Shipping_Mode | Y1: Delivery_Days | Z1: Profit_Margin | AA1: Order_Month | AB1: Order_Year | AC1: Order_Value_Category
A2: 1 | B2: 46080 | C2: C038 | D2: Aarav Mehta | E2: Male | F2: 19 | G2: Mumbai | H2: Maharashtra | I2: West | J2: P009 | K2: Coffee Maker | L2: Home & Kitchen | M2: Appliances | N2: Philips | O2: 2 | P2: 5195.53 | Q2: 0.25 | R2: 7793.3 | S2: 4711.82 | T2: -2299.06 | U2: UPI | V2: Returned | W2: Consumer | X2: Standard | Y2: 1 | Z2: =IFERROR(ECommerceData[[#This Row],[Profit]]/ECommerceData[[#This Row],[Sales]],0) -> -0.29500468 | AA2: =TEXT(B2,"mmm") -> Feb | AB2: =YEAR(B2) -> 2026 | AC2: =IF(ECommerceData[[#This Row],[Sales]]>=50000,"High Value",IF(ECommerceData[[#This Row],[Sales]]>=10000,"Medium Value","Low Value")) -> Low Value
A3: 2 | B3: 46281 | C3: C029 | D3: Vivaan Kapoor | E3: Female | F3: 18 | G3: Lucknow | H3: Uttar Pradesh | I3: North | J3: P001 | K3: Wireless Headphones | L3: Electronics | M3: Audio | N3: Boat | O3: 5 | P3: 2067.49 | Q3: 0.25 | R3: 7753.08 | S3: 5801.77 | T3: 1951.31 | U3: Credit Card | V3: Delivered | W3: Small Business | X3: Express | Y3: 2 | Z3: =IFERROR(ECommerceData[[#This Row],[Profit]]/ECommerceData[[#This Row],[Sales]],0) -> 0.25168191 | AA3: =TEXT(B3,"mmm") -> Sep | AB3: =YEAR(B3) -> 2026 | AC3: =IF(ECommerceData[[#This Row],[Sales]]>=50000,"High Value",IF(ECommerceData[[#This Row],[Sales]]>=10000,"Medium Value","Low Value")) -> Low Value
A4: 3 | B4: 46197 | C4: C023 | D4: Aditya Sharma | E4: Female | F4: 34 | G4: Jaipur | H4: Rajasthan | I4: North | J4: P005 | K4: Bluetooth Speaker | L4: Electronics | M4: Audio | N4: JBL | O4: 2 | P4: 4584.06 | Q4: 0.1 | R4: 8251.31 | S4: 4988.17 | T4: 3263.14 | U4: UPI | V4: Delivered | W4: Small Business | X4: Express | Y4: 1 | Z4: =IFERROR(ECommerceData[[#This Row],[Profit]]/ECommerceData[[#This Row],[Sales]],0) -> 0.39546933 | AA4: =TEXT(B4,"mmm") -> Jun | AB4: =YEAR(B4) -> 2026 | AC4: =IF(ECommerceData[[#This Row],[Sales]]>=50000,"High Value",IF(ECommerceData[[#This Row],[Sales]]>=10000,"Medium Value","Low Value")) -> Low Value
A5: 4 | B5: 46086 | C5: C013 | D5: Arjun Malhotra | E5: Male | F5: 20 | G5: Chennai | H5: Tamil Nadu | I5: South | J5: P003 | K5: Laptop | L5: Electronics | M5: Computers | N5: HP | O5: 5 | P5: 49849.05 | Q5: 0.25 | R5: 186933.95 | S5: 136171.05 | T5: 50762.9 | U5: Credit Card | V5: Delivered | W5: Corporate | X5: Standard | Y5: 5 | Z5: =IFERROR(ECommerceData[[#This Row],[Profit]]/ECommerceData[[#This Row],[Sales]],0) -> 0.27155527 | AA5: =TEXT(B5,"mmm") -> Mar | AB5: =YEAR(B5) -> 2026 | AC5: =IF(ECommerceData[[#This Row],[Sales]]>=50000,"High Value",IF(ECommerceData[[#This Row],[Sales]]>=10000,"Medium Value","Low Value")) -> High Value
A6: 5 | B6: 46142 | C6: C043 | D6: Rohan Desai | E6: Male | F6: 28 | G6: Pune | H6: Maharashtra | I6: West | J6: P013 | K6: Face Wash | L6: Beauty | M6: Skincare | N6: Nivea | O6: 3 | P6: 445.81 | Q6: 0.1 | R6: 1203.68 | S6: 745.12 | T6: 458.56 | U6: Net Banking | V6: Delivered | W6: Small Business | X6: Standard | Y6: 2 | Z6: =IFERROR(ECommerceData[[#This Row],[Profit]]/ECommerceData[[#This Row],[Sales]],0) -> 0.38096504 | AA6: =TEXT(B6,"mmm") -> Apr | AB6: =YEAR(B6) -> 2026 | AC6: =IF(ECommerceData[[#This Row],[Sales]]>=50000,"High Value",IF(ECommerceData[[#This Row],[Sales]]>=10000,"Medium Value","Low Value")) -> Low Value
A7: 6 | B7: 46106 | C7: C021 | D7: Kabir Shah | E7: Male | F7: 32 | G7: Hyderabad | H7: Telangana | I7: South | J7: P013 | K7: Face Wash | L7: Beauty | M7: Skincare | N7: Nivea | O7: 3 | P7: 494.06 | Q7: 0.25 | R7: 1111.63 | S7: 828.34 | T7: 283.29 | U7: UPI | V7: Delivered | W7: Corporate | X7: Express | Y7: 6 | Z7: =IFERROR(ECommerceData[[#This Row],[Profit]]/ECommerceData[[#This Row],[Sales]],0) -> 0.25484199 | AA7: =TEXT(B7,"mmm") -> Mar | AB7: =YEAR(B7) -> 2026 | AC7: =IF(ECommerceData[[#This Row],[Sales]]>=50000,"High Value",IF(ECommerceData[[#This Row],[Sales]]>=10000,"Medium Value","Low Value")) -> Low Value
A8: 7 | B8: 46160 | C8: C057 | D8: Vihaan Patel | E8: Female | F8: 27 | G8: Pune | H8: Maharashtra | I8: West | J8: P007 | K8: T-Shirt | L8: Fashion | M8: Clothing | N8: Puma | O8: 5 | P8: 967.75 | Q8: 0.1 | R8: 4354.86 | S8: 2748.05 | T8: 1606.81 | U8: Debit Card | V8: Delivered | W8: Consumer | X8: Standard | Y8: 4 | Z8: =IFERROR(ECommerceData[[#This Row],[Profit]]/ECommerceData[[#This Row],[Sales]],0) -> 0.36896938 | AA8: =TEXT(B8,"mmm") -> May | AB8: =YEAR(B8) -> 2026 | AC8: =IF(ECommerceData[[#This Row],[Sales]]>=50000,"High Value",IF(ECommerceData[[#This Row],[Sales]]>=10000,"Medium Value","Low Value")) -> Low Value
A9: 8 | B9: 46157 | C9: C032 | D9: Reyansh Joshi | E9: Male | F9: 25 | G9: Lucknow | H9: Uttar Pradesh | I9: North | J9: P014 | K9: Perfume | L9: Beauty | M9: Fragrance | N9: Fogg | O9: 5 | P9: 1175.86 | Q9: 0.05 | R9: 5585.32 | S9: 4576.37 | T9: 1008.94 | U9: Credit Card | V9: Delivered | W9: Small Business | X9: Standard | Y9: 5 | Z9: =IFERROR(ECommerceData[[#This Row],[Profit]]/ECommerceData[[#This Row],[Sales]],0) -> 0.1806414 | AA9: =TEXT(B9,"mmm") -> May | AB9: =YEAR(B9) -> 2026 | AC9: =IF(ECommerceData[[#This Row],[Sales]]>=50000,"High Value",IF(ECommerceData[[#This Row],[Sales]]>=10000,"Medium Value","Low Value")) -> Low Value
A10: 9 | B10: 46239 | C10: C056 | D10: Ishaan Verma | E10: Male | F10: 52 | G10: Lucknow | H10: Uttar Pradesh | I10: North | J10: P003 | K10: Laptop | L10: Electronics | M10: Computers | N10: HP | O10: 4 | P10: 50768.84 | Q10: 0.15 | R10: 0 | S10: 122035.97 | T10: 0 | U10: Debit Card | V10: Cancelled | W10: Small Business | X10: Express | Y10: 0 | Z10: =IFERROR(ECommerceData[[#This Row],[Profit]]/ECommerceData[[#This Row],[Sales]],0) -> 0 | AA10: =TEXT(B10,"mmm") -> Aug | AB10: =YEAR(B10) -> 2026 | AC10: =IF(ECommerceData[[#This Row],[Sales]]>=50000,"High Value",IF(ECommerceData[[#This Row],[Sales]]>=10000,"Medium Value","Low Value")) -> Low Value
A11: 10 | B11: 46080 | C11: C049 | D11: Dhruv Nair | E11: Male | F11: 37 | G11: Jaipur | H11: Rajasthan | I11: North | J11: P014 | K11: Perfume | L11: Beauty | M11: Fragrance | N11: Fogg | O11: 2 | P11: 1188.89 | Q11: 0.25 | R11: 1783.34 | S11: 1409.2 | T11: 374.14 | U11: Net Banking | V11: Delivered | W11: Small Business | X11: Standard | Y11: 5 | Z11: =IFERROR(ECommerceData[[#This Row],[Profit]]/ECommerceData[[#This Row],[Sales]],0) -> 0.20979735 | AA11: =TEXT(B11,"mmm") -> Feb | AB11: =YEAR(B11) -> 2026 | AC11: =IF(ECommerceData[[#This Row],[Sales]]>=50000,"High Value",IF(ECommerceData[[#This Row],[Sales]]>=10000,"Medium Value","Low Value")) -> Low Value
A12: 11 | B12: 46101 | C12: C021 | D12: Aanya Mehta | E12: Male | F12: 25 | G12: Bengaluru | H12: Karnataka | I12: South | J12: P006 | K12: Running Shoes | L12: Fashion | M12: Footwear | N12: Nike | O12: 5 | P12: 4908.15 | Q12: 0.2 | R12: 0 | S12: 15714.69 | T12: 0 | U12: Debit Card | V12: Cancelled | W12: Corporate | X12: Standard | Y12: 0 | Z12: =IFERROR(ECommerceData[[#This Row],[Profit]]/ECommerceData[[#This Row],[Sales]],0) -> 0 | AA12: =TEXT(B12,"mmm") -> Mar | AB12: =YEAR(B12) -> 2026 | AC12: =IF(ECommerceData[[#This Row],[Sales]]>=50000,"High Value",IF(ECommerceData[[#This Row],[Sales]]>=10000,"Medium Value","Low Value")) -> Low Value
A13: 12 | B13: 46052 | C13: C050 | D13: Anaya Kapoor | E13: Male | F13: 48 | G13: Delhi | H13: Delhi | I13: North | J13: P003 | K13: Laptop | L13: Electronics | M13: Computers | N13: HP | O13: 1 | P13: 54411.84 | Q13: 0 | R13: 0 | S13: 44330.21 | T13: 0 | U13: Net Banking | V13: Cancelled | W13: Consumer | X13: Express | Y13: 0 | Z13: =IFERROR(ECommerceData[[#This Row],[Profit]]/ECommerceData[[#This Row],[Sales]],0) -> 0 | AA13: =TEXT(B13,"mmm") -> Jan | AB13: =YEAR(B13) -> 2026 | AC13: =IF(ECommerceData[[#This Row],[Sales]]>=50000,"High Value",IF(ECommerceData[[#This Row],[Sales]]>=10000,"Medium Value","Low Value")) -> Low Value
... A101: 100 | B101: 46061 | C101: C042 | D101: Rishi Nair | E101: Female | F101: 38 | G101: Ahmedabad | H101: Gujarat | I101: West | J101: P016 | K101: Notebook Set | L101: Stationery | M101: Office | N101: Classmate | O101: 4 | P101: 367.81 | Q101: 0.2 | R101: 0 | S101: 809.46 | T101: 0 | U101: Credit Card | V101: Cancelled | W101: Corporate | X101: Standard | Y101: 0 | Z101: =IFERROR(ECommerceData[[#This Row],[Profit]]/ECommerceData[[#This Row],[Sales]],0) -> 0 | AA101: =TEXT(B101,"mmm") -> Feb | AB101: =YEAR(B101) -> 2026 | AC101: =IF(ECommerceData[[#This Row],[Sales]]>=50000,"High Value",IF(ECommerceData[[#This Row],[Sales]]>=10000,"Medium Value","Low Value")) -> Low Value

Sheet Analysis
A1: KPI | B1: Value
A2: Total Sales | B2: =SUM(Data!R:R) -> 1215940.8
A3: Total Profit | B3: =SUM(Data!T:T) -> 289024.25
A4: Total Orders | B4: =COUNTA(Data!A:A)-1 -> 100
A5: Total Quantity | B5: =SUM(Data!O:O) -> 296
A6: Average Order Value | B6: =B2/B4 -> 12159.408
A7: Average Profit Margin | B7: =AVERAGE(Data!Z:Z) -> 0.16899236
A8: Average Delivery Days | B8: =AVERAGE(Data!Y:Y) -> 3.48
A11: Row Labels | B11: Total Sales | C11: Total Profit | D11: Total Orders | E11: Total Quantity | F11: Average Order Value | G11: Average of Profit_Margin
A12: East | B12: 202813.21 | C12: 57541.52 | D12: 11 | E12: 26 | F12: 18437.565 | G12: 1.1256402
A13: North | B13: 519365.2 | C13: 116200.69 | D13: 35 | E13: 109 | F13: 14839.006 | G13: 0.86545538
A14: South | B14: 371481.99 | C14: 91725.76 | D14: 29 | E14: 92 | F14: 12809.724 | G14: 1.0243758
A15: West | B15: 122280.39 | C15: 23556.28 | D15: 25 | E15: 69 | F15: 4891.2156 | G15: 1.1048048
A16: Grand Total | B16: 1215940.8 | C16: 289024.25 | D16: 100 | E16: 296 | F16: 12159.408 | G16: 1
A25: Row Labels | B25: Sum of Sales
A26: Beauty | B26: 65189.65
A27: Electronics | B27: 976659.41
A28: Fashion | B28: 67390.05
A29: Home & Kitchen | B29: 92813.5
A30: Stationery | B30: 13888.18
A31: Grand Total | B31: 1215940.8
A40: Row Labels | B40: Sum of Profit
A41: Beauty | B41: 10097.43
A42: Electronics | B42: 263677.31
A43: Fashion | B43: 7790.56
A44: Home & Kitchen | B44: 4069.57
A45: Stationery | B45: 3389.38
A46: Grand Total | B46: 289024.25
A55: Row Labels | B55: Sum of Sales
A56: Jan | B56: 236007.09
A57: Feb | B57: 68313.77
A58: Mar | B58: 569359.23
A59: Apr | B59: 91885.13
A60: May | B60: 46589.04
A61: Jun | B61: 42355.22
A62: Jul | B62: 88955.78
A63: Aug | B63: 16804.75
A64: Sep | B64: 55670.78
A65: Grand Total | B65: 1215940.8
A75: Row Labels | B75: Sum of Sales
...

Sheet Executive Dashboard
AG11: 7.48 cm
AD16: 5.82 cm
AJ22: 7.62 cm
AJ24: 12.76 cm
